WARNING:root:The OGB package is out of date. Your version is 1.3.1, while the latest version is 1.3.5.
Using backend: pytorch
NVIDIA GeForce RTX 3090 0
{'dataset_name': 'ogbg-molpcba', 'basis': 'GSO', 'epsilon': [-0.1, -0.2, -0.3, -0.4], 'power': [[1, 4], [1, 4], [1, 7], [1, 7]], 'seeds': [0, 1, 2, 3, 4], 'num_workers': 4, 'hyperparams': {'batch_size': 64, 'epochs': 30, 'learning_rate': 0.0005, 'decay_rate': 0.2, 'milestones': [10, 15, 20], 'weight_decay': 0.0005, 'warmup_epochs': 0}, 'architecture': {'layers': 8, 'hidden': 256, 'pooling': 'X', 'dropout': 0}, 'commit_id': 'c8173a77747f8198406f5d7812d420ebfe058a5e', 'time_stamp': '1673867573', 'directory': '../../../results_spectral_rotation/RTX3090/ogbg-molpcba/'}
{'dataset_name': 'ogbg-molpcba', 'basis': 'GSO', 'epsilon': [-0.1, -0.2, -0.3, -0.4], 'power': [[1, 4], [1, 4], [1, 7], [1, 7]], 'seeds': [0, 1, 2, 3, 4], 'num_workers': 4, 'hyperparams': {'batch_size': 64, 'epochs': 30, 'learning_rate': 0.0005, 'decay_rate': 0.2, 'milestones': [10, 15, 20], 'weight_decay': 0.0005, 'warmup_epochs': 0}, 'architecture': {'layers': 8, 'hidden': 256, 'pooling': 'X', 'dropout': 0}, 'commit_id': 'c8173a77747f8198406f5d7812d420ebfe058a5e', 'time_stamp': 1673867574, 'directory': '../../../results_spectral_rotation/RTX3090/ogbg-molpcba/', 'seed': 0}
Loading the cached file... (NOTE: delete it if you change the preprocessing settings)
Traceback (most recent call last):
  File "/home/rtx/workspace/spectral_rotation/ogbg/graphml/ogbg/mol/./main.py", line 312, in <module>
    main()
  File "/home/rtx/workspace/spectral_rotation/ogbg/graphml/ogbg/mol/./main.py", line 119, in main
    epoch_idx, train_curve, valid_curve, test_curve, trainL_curve, task_type = run_with_given_seed(config, ts_fk_algo_hp)
  File "/home/rtx/workspace/spectral_rotation/ogbg/graphml/ogbg/mol/./main.py", line 174, in run_with_given_seed
    dataset = DglGraphPropPred(name=config.dataset_name)
  File "/home/rtx/anaconda3/envs/graphml/lib/python3.9/site-packages/ogb/graphproppred/dataset_dgl.py", line 68, in __init__
    self.pre_process()
  File "/home/rtx/workspace/spectral_rotation/ogbg/graphml/ogbg/mol/../../ogbg/data_preparation.py", line 35, in pre_process
    self.graphs, label_dict = load_graphs(pre_processed_file_path)
  File "/home/rtx/anaconda3/envs/graphml/lib/python3.9/site-packages/dgl/data/graph_serialize.py", line 182, in load_graphs
    return load_graph_v2(filename, idx_list)
  File "/home/rtx/anaconda3/envs/graphml/lib/python3.9/site-packages/dgl/data/graph_serialize.py", line 192, in load_graph_v2
    heterograph_list = _CAPI_LoadGraphFiles_V2(filename, idx_list)
  File "dgl/_ffi/_cython/./function.pxi", line 287, in dgl._ffi._cy3.core.FunctionBase.__call__
  File "dgl/_ffi/_cython/./function.pxi", line 222, in dgl._ffi._cy3.core.FuncCall
  File "dgl/_ffi/_cython/./function.pxi", line 211, in dgl._ffi._cy3.core.FuncCall3
  File "dgl/_ffi/_cython/./base.pxi", line 155, in dgl._ffi._cy3.core.CALL
dgl._ffi.base.DGLError: [19:13:03] /opt/dgl/src/graph/heterograph.cc:508: Check failed: fs->Read(&magicNum): Invalid Magic Number
Stack trace:
  [bt] (0) /home/rtx/anaconda3/envs/graphml/lib/python3.9/site-packages/dgl/libdgl.so(dmlc::LogMessageFatal::~LogMessageFatal()+0x4f) [0x7f72508159cf]
  [bt] (1) /home/rtx/anaconda3/envs/graphml/lib/python3.9/site-packages/dgl/libdgl.so(dgl::HeteroGraph::Load(dmlc::Stream*)+0x91) [0x7f7251010be1]
  [bt] (2) /home/rtx/anaconda3/envs/graphml/lib/python3.9/site-packages/dgl/libdgl.so(dgl::serialize::LoadHeteroGraphs(std::string const&, std::vector<unsigned long, std::allocator<unsigned long> >)+0x1335) [0x7f72510a3c05]
  [bt] (3) /home/rtx/anaconda3/envs/graphml/lib/python3.9/site-packages/dgl/libdgl.so(+0xe32f7f) [0x7f725109bf7f]
  [bt] (4) /home/rtx/anaconda3/envs/graphml/lib/python3.9/site-packages/dgl/libdgl.so(DGLFuncCall+0x48) [0x7f7250fa8e88]
  [bt] (5) /home/rtx/anaconda3/envs/graphml/lib/python3.9/site-packages/dgl/_ffi/_cy3/core.cpython-39-x86_64-linux-gnu.so(+0x16ca2) [0x7f728982bca2]
  [bt] (6) /home/rtx/anaconda3/envs/graphml/lib/python3.9/site-packages/dgl/_ffi/_cy3/core.cpython-39-x86_64-linux-gnu.so(+0x16f5b) [0x7f728982bf5b]
  [bt] (7) python(_PyObject_MakeTpCall+0x316) [0x5601e5379406]
  [bt] (8) python(_PyEval_EvalFrameDefault+0x4e12) [0x5601e54168e2]


